Workbook
Name _Hlk206094987: '5.10'!$A$27
Name _Hlk210243911: '5.11'!#REF!

Sheet Cuprins
B2: Recensământul Populației și Locuințelor 2024: CARACTERISTICI ETNO-CULTURALE
B4: 5.1 Populația după etnie, pe medii de reședință, la recensămintele din 2024 și 2014
B5: 5.2 Populația după etnie, pe grupe de vârstă, la recensământul din 2024
B6: 5.3 Populația după etnie, pe sexe și medii de reședință, la recensământul din 2024
B7: 5.4 Populația după etnie, pe regiuni de dezvoltare și raioane/municipii, la recensământul din 2024
B8: 5.5 Populația după etnie, pe regiuni de dezvoltare și raioane, la recensământul din 2024
B9: 5.6 Populația după etnie, pe orașe (municipii) și sate (comune), la recensământul din 2024
B10: 5.7 Populația după etnie pe orașe (municipii) și sate (comune), la recensământul din 2024
B11: 5.8 Populația după prima și a doua etnie declarată la recensământul din 2024
B12: 5.9 Populația după prima și a doua etnie declarată pe regiuni de dezvoltare, la recensământul din 2024
B13: 5.10 Populația după limba maternă, pe medii de reședință, la recensămintele din 2024 și 2014
B14: 5.11 Populația după limba maternă, pe grupe de vârstă, la recensământul din 2024
... B44: 5.41 Populația de 3 ani și peste după etnie și cunoașterea limbilor (competențe lingvistice)

Sheet 5.1
B1: Cuprins
B3: =Cuprins!B2 -> Recensământul Populației și Locuințelor 2024: CARACTERISTICI ETNO-CULTURALE
B5: 5.1 Populația după etnie, pe medii de reședință, la recensămintele din 2024 și 20141,2
H7: persoane, %
B8: Etnia declarată | C8: 2024 | F8: 2014
C9: persoane | D9: în % față de total populație | E9: în % față de cei care au declarat limba maternă | F9: persoane | G9: în % față de total populație | H9: în % față de cei care au declarat limba maternă
B10: A | C10: 1 | D10: 2 | E10: 3 | F10: 4 | G10: 5 | H10: 6
B11: Total
B12: Total | C12: 2409207 | D12: =C12/C$12 * 100 -> 100 | E12: x | F12: 2595771 | G12: 100 | H12: x
B13: Moldoveni | C13: 1848670 | D13: =C13/C$12 * 100 -> 76.733548 | E13: =C13/SUM(C13:C20) * 100 -> 76.843524 | F13: 1921527 | G13: =F13/F$12 * 100 -> 74.02529 | H13: =F13/SUM(F13:F20) * 100 -> 75.308903
B14: Români | C14: 193197 | D14: =C14/C$12 * 100 -> 8.0191117 | E14: =C14/SUM(C13:C20) * 100 -> 8.0306049 | F14: 170881 | G14: =F14/F$12 * 100 -> 6.5830537 | H14: =F14/SUM(F13:F20) * 100 -> 6.6972052
B15: Ucraineni | C15: 123586 | D15: =C15/C$12 * 100 -> 5.1297377 | E15: =C15/SUM(C13:C20) * 100 -> 5.1370898 | F15: 172342 | G15: =F15/F$12 * 100 -> 6.6393376 | H15: =F15/SUM(F13:F20) * 100 -> 6.7544651
B16: Ruși | C16: 81630 | D16: =C16/C$12 * 100 -> 3.3882518 | E16: =C16/SUM(C13:C20) * 100 -> 3.393108 | F16: 105656 | G16: =F16/F$12 * 100 -> 4.0703128 | H16: =F16/SUM(F13:F20) * 100 -> 4.1408929
B17: Găgăuzi | C17: 97205 | D17: =C17/C$12 * 100 -> 4.0347301 | E17: =C17/SUM(C13:C20) * 100 -> 4.0405128 | F17: 112289 | G17: =F17/F$12 * 100 -> 4.3258438 | H17: =F17/SUM(F13:F20) * 100 -> 4.4008549
B18: Bulgari | C18: 38236 | D18: =C18/C$12 * 100 -> 1.5870782 | E18: =C18/SUM(C13:C20) * 100 -> 1.5893529 | F18: 47414 | G18: =F18/F$12 * 100 -> 1.8265864 | H18: =F18/SUM(F13:F20) * 100 -> 1.8582598
B19: Romi/Țigani | C19: 9356 | D19: =C19/C$12 * 100 -> 0.38834355 | E19: =C19/SUM(C13:C20) * 100 -> 0.38890014 | F19: 8525 | G19: =F19/F$12 * 100 -> 0.3284188 | H19: =F19/SUM(F13:F20) * 100 -> 0.33411365
B20: Alte etnii | C20: 13879 | D20: =C20/C$12 * 100 -> 0.57608167 | E20: =C20/SUM(C13:C20) * 100 -> 0.57690733 | F20: 12893 | G20: =F20/F$12 * 100 -> 0.4966925 | H20: =F20/SUM(F13:F20) * 100 -> 0.50530525
B21: Nu au declarat etnia | C21: 3448 | D21: =C21/C$12 * 100 -> 0.14311763 | E21: x | F21: 44244 | G21: =F21/F$12 * 100 -> 1.7044647 | H21: x
B22: din total, pe medii de reședință
B23: Urban
B24: Total | C24: 1118967 | D24: =C24/C$24 * 100 -> 100 | E24: x | F24: 901694 | G24: 100 | H24: x
B25: Moldoveni | C25: 788272 | D25: =C25/C$24 * 100 -> 70.446403 | E25: =C25/SUM(C25:C32) * 100 -> 70.613001 | F25: 550887 | G25: =F25/F$24*100 -> 61.094673 | H25: =F25/SUM(F25:F32) * 100 -> 63.422477
B26: Români | C26: 109809 | D26: =C26/C$24 * 100 -> 9.8134261 | E26: =C26/SUM(C25:C32) * 100 -> 9.8366339 | F26: 80277 | G26: =F26/F$24*100 -> 8.9029094 | H26: =F26/SUM(F25:F32) * 100 -> 9.2421244
B27: Ucraineni | C27: 70207 | D27: =C27/C$24 * 100 -> 6.274269 | E27: =C27/SUM(C25:C32) * 100 -> 6.289107 | F27: 75981 | G27: =F27/F$24*100 -> 8.4264728 | H27: =F27/SUM(F25:F32) * 100 -> 8.7475348
B28: Ruși | C28: 66054 | D28: =C28/C$24 * 100 -> 5.9031231 | E28: =C28/SUM(C25:C32) * 100 -> 5.9170834 | F28: 79688 | G28: =F28/F$24*100 -> 8.8375879 | H28: =F28/SUM(F25:F32) * 100 -> 9.174314
B29: Găgăuzi | C29: 41360 | D29: =C29/C$24 * 100 -> 3.6962663 | E29: =C29/SUM(C25:C32) * 100 -> 3.7050076 | F29: 41447 | G29: =F29/F$24*100 -> 4.5965705 | H29: =F29/SUM(F25:F32) * 100 -> 4.7717071
B30: Bulgari | C30: 22763 | D30: =C30/C$24 * 100 -> 2.034287 | E30: =C30/SUM(C25:C32) * 100 -> 2.0390979 | F30: 24914 | G30: =F30/F$24*100 -> 2.7630216 | H30: =F30/SUM(F25:F32) * 100 -> 2.8682971
B31: Romi/Țigani | C31: 6173 | D31: =C31/C$24 * 100 -> 0.55166953 | E31: =C31/SUM(C25:C32) * 100 -> 0.55297417 | F31: 5831 | G31: =F31/F$24*100 -> 0.64667171 | H31: =F31/SUM(F25:F32) * 100 -> 0.67131093
B32: Alte etnii | C32: 11689 | D32: =C32/C$24 * 100 -> 1.0446242 | E32: =C32/SUM(C25:C32) * 100 -> 1.0470946 | F32: 9574 | G32: =F32/F$24*100 -> 1.0617793 | H32: =F32/SUM(F25:F32) * 100 -> 1.1022347
B33: Nu au declarat etnia | C33: 2640 | D33: =C33/C$24 * 100 -> 0.23593189 | E33: x | F33: 33095 | G33: =F33/F$24*100 -> 3.6703139 | H33: x
B34: Rural
B35: Total | C35: 1290240 | D35: =C35/C$35 * 100 -> 100 | E35: x | F35: 1694077 | G35: 100 | H35: x
B36: Moldoveni | C36: 1060398 | D36: =C36/C$35 * 100 -> 82.186105 | E36: =C36/SUM(C36:C43) * 100 -> 82.237605 | F36: 1370640 | G36: =F36/F$35*100 -> 80.907775 | H36: =F36/SUM(F36:F43) * 100 -> 81.443769
B37: Români | C37: 83388 | D37: =C37/C$35 * 100 -> 6.4629836 | E37: =C37/SUM(C36:C43) * 100 -> 6.4670335 | F37: 90604 | G37: =F37/F$35*100 -> 5.3482811 | H37: =F37/SUM(F36:F43) * 100 -> 5.3837122
B38: Ucraineni | C38: 53379 | D38: =C38/C$35 * 100 -> 4.1371373 | E38: =C38/SUM(C36:C43) * 100 -> 4.1397297 | F38: 96361 | G38: =F38/F$35*100 -> 5.6881122 | H38: =F38/SUM(F36:F43) * 100 -> 5.7257946
B39: Ruși | C39: 15576 | D39: =C39/C$35 * 100 -> 1.2072173 | E39: =C39/SUM(C36:C43) * 100 -> 1.2079737 | F39: 25968 | G39: =F39/F$35*100 -> 1.5328701 | H39: =F39/SUM(F36:F43) * 100 -> 1.543025
B40: Găgăuzi | C40: 55845 | D40: =C40/C$35 * 100 -> 4.3282645 | E40: =C40/SUM(C36:C43) * 100 -> 4.3309767 | F40: 70842 | G40: =F40/F$35*100 -> 4.1817462 | H40: =F40/SUM(F36:F43) * 100 -> 4.2094492
B41: Bulgari | C41: 15473 | D41: =C41/C$35 * 100 -> 1.1992343 | E41: =C41/SUM(C36:C43) * 100 -> 1.1999857 | F41: 22500 | G41: =F41/F$35*100 -> 1.3281569 | H41: =F41/SUM(F36:F43) * 100 -> 1.3369556
B42: Romi/Țigani | C42: 3183 | D42: =C42/C$35 * 100 -> 0.24669829 | E42: =C42/SUM(C36:C43) * 100 -> 0.24685288 | F42: 2694 | G42: =F42/F$35*100 -> 0.15902465 | H42: =F42/SUM(F36:F43) * 100 -> 0.16007815
B43: Alte etnii | C43: 2190 | D43: =C43/C$35 * 100 -> 0.16973586 | E43: =C43/SUM(C36:C43) * 100 -> 0.16984223 | F43: 3319 | G43: =F43/F$35*100 -> 0.1959179 | H43: =F43/SUM(F36:F43) * 100 -> 0.1972158
...

Sheet 5.2
B1: Cuprins
B3: =Cuprins!B2 -> Recensământul Populației și Locuințelor 2024: CARACTERISTICI ETNO-CULTURALE
B5: 5.2 Populația după etnie, pe grupe de vârstă, la recensământul din 20241,2
C6: persoane
B7: Etnia declarată | C7: Total | D7: Grupe de vârstă, ani
D8: 0-9 | E8: 10-19 | F8: 20-29 | G8: 30-39 | H8: 40-49 | I8: 50-59 | J8: 60-69 | K8: 70-79 | L8: 80 și mai mult
B9: A | C9: 1 | D9: 2 | E9: 3 | F9: 4 | G9: 5 | H9: 6 | I9: 7 | J9: 8 | K9: 9 | L9: 10
B10: Total | C10: 2409207 | D10: 301844 | E10: 305993 | F10: 219015 | G10: 335638 | H10: 324962 | I10: 302081 | J10: 358444 | K10: 198811 | L10: 62419
B11: Moldoveni | C11: 1848670 | D11: 245773 | E11: 244703 | F11: 175170 | G11: 267078 | H11: 249875 | I11: 227300 | J11: 259528 | K11: 137185 | L11: 42058
B12: Români | C12: 193197 | D12: 24631 | E12: 24479 | F12: 15894 | G12: 25137 | H12: 25971 | I12: 24349 | J12: 31191 | K12: 17688 | L12: 3857
B13: Ucraineni | C13: 123586 | D13: 7647 | E13: 9864 | F13: 8258 | G13: 13588 | H13: 16171 | I13: 18746 | J13: 24842 | K13: 16971 | L13: 7499
B14: Ruși | C14: 81630 | D14: 5331 | E14: 7224 | F14: 4718 | G14: 8540 | H14: 11217 | I14: 11977 | J14: 15609 | K14: 12266 | L14: 4748
B15: Găgăuzi | C15: 97205 | D15: 11923 | E15: 12096 | F15: 8421 | G15: 13276 | H15: 12431 | I15: 11568 | J15: 17057 | K15: 8262 | L15: 2171
B16: Bulgari | C16: 38236 | D16: 3215 | E16: 4001 | F16: 2823 | G16: 4761 | H16: 5729 | I16: 5076 | J16: 6791 | K16: 4465 | L16: 1375
B17: Romi/Țigani | C17: 9356 | D17: 1700 | E17: 1676 | F17: 1237 | G17: 1243 | H17: 1227 | I17: 947 | J17: 903 | K17: 355 | L17: 68
B18: Alte etnii | C18: 13879 | D18: 879 | E18: 1432 | F18: 2200 | G18: 1578 | H18: 1824 | I18: 1739 | J18: 2175 | K18: 1454 | L18: 598
B19: Nu au declarat etnia | C19: 3448 | D19: 745 | E19: 518 | F19: 294 | G19: 437 | H19: 517 | I19: 379 | J19: 348 | K19: 165 | L19: 45
B20: în % față de total
B21: Total | C21: 100 | D21: =D10/$C$10*100 -> 12.52877 | E21: =E10/$C$10*100 -> 12.700984 | F21: =F10/$C$10*100 -> 9.0907506 | G21: =G10/$C$10*100 -> 13.931472 | H21: =H10/$C$10*100 -> 13.488339 | I21: =I10/$C$10*100 -> 12.538607 | J21: =J10/$C$10*100 -> 14.878091 | K21: =K10/$C$10*100 -> 8.2521344 | L21: =L10/$C$10*100 -> 2.5908525
B22: Moldoveni | C22: 100 | D22: =D11/$C$11*100 -> 13.294585 | E22: =E11/$C$11*100 -> 13.236705 | F22: =F11/$C$11*100 -> 9.4754607 | G22: =G11/$C$11*100 -> 14.447035 | H22: =H11/$C$11*100 -> 13.516474 | I22: =I11/$C$11*100 -> 12.295326 | J22: =J11/$C$11*100 -> 14.038633 | K22: =K11/$C$11*100 -> 7.4207403 | L22: =L11/$C$11*100 -> 2.275041
B23: Români | C23: 100 | D23: =D12/$C$12*100 -> 12.749163 | E23: =E12/$C$12*100 -> 12.670487 | F23: =F12/$C$12*100 -> 8.2268358 | G23: =G12/$C$12*100 -> 13.011072 | H23: =H12/$C$12*100 -> 13.442755 | I23: =I12/$C$12*100 -> 12.603198 | J23: =J12/$C$12*100 -> 16.144661 | K23: =K12/$C$12*100 -> 9.1554217 | L23: =L12/$C$12*100 -> 1.9964078
B24: Ucraineni | C24: 100 | D24: =D13/$C$13*100 -> 6.1875941 | E24: =E13/$C$13*100 -> 7.9814866 | F24: =F13/$C$13*100 -> 6.6819866 | G24: =G13/$C$13*100 -> 10.994773 | H24: =H13/$C$13*100 -> 13.084815 | I24: =I13/$C$13*100 -> 15.168385 | J24: =J13/$C$13*100 -> 20.100982 | K24: =K13/$C$13*100 -> 13.732138 | L24: =L13/$C$13*100 -> 6.0678394
B25: Ruși | C25: 100 | D25: =D14/$C$14*100 -> 6.5306872 | E25: =E14/$C$14*100 -> 8.8496876 | F25: =F14/$C$14*100 -> 5.7797378 | G25: =G14/$C$14*100 -> 10.46184 | H25: =H14/$C$14*100 -> 13.741272 | I25: =I14/$C$14*100 -> 14.672302 | J25: =J14/$C$14*100 -> 19.121646 | K25: =K14/$C$14*100 -> 15.026338 | L25: =L14/$C$14*100 -> 5.816489
B26: Găgăuzi | C26: 100 | D26: =D15/$C$15*100 -> 12.26583 | E26: =E15/$C$15*100 -> 12.443804 | F26: =F15/$C$15*100 -> 8.6631346 | G26: =G15/$C$15*100 -> 13.657734 | H26: =H15/$C$15*100 -> 12.788437 | I26: =I15/$C$15*100 -> 11.900622 | J26: =J15/$C$15*100 -> 17.547451 | K26: =K15/$C$15*100 -> 8.4995628 | L26: =L15/$C$15*100 -> 2.2334242
B27: Bulgari | C27: 100 | D27: =D16/$C$16*100 -> 8.4083063 | E27: =E16/$C$16*100 -> 10.463961 | F27: =F16/$C$16*100 -> 7.3830945 | G27: =G16/$C$16*100 -> 12.451616 | H27: =H16/$C$16*100 -> 14.983262 | I27: =I16/$C$16*100 -> 13.275447 | J27: =J16/$C$16*100 -> 17.760749 | K27: =K16/$C$16*100 -> 11.677477 | L27: =L16/$C$16*100 -> 3.5960875
B28: Romi/Țigani | C28: 100 | D28: =D17/$C$17*100 -> 18.170158 | E28: =E17/$C$17*100 -> 17.913638 | F28: =F17/$C$17*100 -> 13.221462 | G28: =G17/$C$17*100 -> 13.285592 | H28: =H17/$C$17*100 -> 13.114579 | I28: =I17/$C$17*100 -> 10.121847 | J28: =J17/$C$17*100 -> 9.6515605 | K28: =K17/$C$17*100 -> 3.7943566 | L28: =L17/$C$17*100 -> 0.72680633
B29: Alte etnii | C29: 100 | D29: =D18/$C$18*100 -> 6.3333093 | E29: =E18/$C$18*100 -> 10.317746 | F29: =F18/$C$18*100 -> 15.851286 | G29: =G18/$C$18*100 -> 11.369695 | H29: =H18/$C$18*100 -> 13.142157 | I29: =I18/$C$18*100 -> 12.529721 | J29: =J18/$C$18*100 -> 15.671158 | K29: =K18/$C$18*100 -> 10.476259 | L29: =L18/$C$18*100 -> 4.3086678
B30: Nu au declarat etnia | C30: 100 | D30: =D19/$C$19*100 -> 21.606729 | E30: =E19/$C$19*100 -> 15.023202 | F30: =F19/$C$19*100 -> 8.5266821 | G30: =G19/$C$19*100 -> 12.674014 | H30: =H19/$C$19*100 -> 14.9942 | I30: =I19/$C$19*100 -> 10.991879 | J30: =J19/$C$19*100 -> 10.092807 | K30: =K19/$C$19*100 -> 4.7853828 | L30: =L19/$C$19*100 -> 1.3051044
B32: 1Datele se referă doar la UAT efectiv recenzate și nu includ unitățile administrativ-teritoriale din stânga Nistrului, municipiului Bender (inclusiv satul Proteagailovca), comuna Chițcani (inclusiv satele Merenești și Zahorna), satele Cremenciug și Gîsca din raionul Căușeni, comuna Corjova (inclusiv satul Mahala) din raionul Dubăsari, precum și satul Roghi din cadrul comunei Molovata Nouă, raionul Dubăsari.
B33: ² Datele pentru "Populație" sunt prezentate pentru populația cu reședință obișnuită.

Sheet 5.3
B1: Cuprins
B3: =Cuprins!B2 -> Recensământul Populației și Locuințelor 2024: CARACTERISTICI ETNO-CULTURALE
B5: 5.3 Populația după etnie, pe sexe și medii de reședință, la recensământul din 20241,2
G7: persoane
B8: Etnia declarată | C8: Total | D8: Sexe | F8: Medii de reședință
D9: Masculin | E9: Feminin | F9: Urban | G9: Rural
B10: A | C10: 1 | D10: 2 | E10: 3 | F10: 4 | G10: 5
B11: Total | C11: 2409207 | D11: 1137343 | E11: 1271864 | F11: 1118967 | G11: 1290240
B12: Moldoveni | C12: 1848670 | D12: 879929 | E12: 968741 | F12: 788272 | G12: 1060398
B13: Români | C13: 193197 | D13: 93142 | E13: 100055 | F13: 109809 | G13: 83388
B14: Ucraineni | C14: 123586 | D14: 52839 | E14: 70747 | F14: 70207 | G14: 53379
B15: Ruși | C15: 81630 | D15: 34139 | E15: 47491 | F15: 66054 | G15: 15576
B16: Găgăuzi | C16: 97205 | D16: 46317 | E16: 50888 | F16: 41360 | G16: 55845
B17: Bulgari | C17: 38236 | D17: 17678 | E17: 20558 | F17: 22763 | G17: 15473
B18: Romi/Țigani | C18: 9356 | D18: 4402 | E18: 4954 | F18: 6173 | G18: 3183
B19: Alte etnii | C19: 13879 | D19: 7217 | E19: 6662 | F19: 11689 | G19: 2190
B20: Nu au declarat etnia | C20: 3448 | D20: 1680 | E20: 1768 | F20: 2640 | G20: 808
B21: în % față de total
B22: Total | C22: 100 | D22: =D11/C11*100 -> 47.208189 | E22: =E11/C11*100 -> 52.791811 | F22: =F11/C11*100 -> 46.445449 | G22: =G11/C11*100 -> 53.554551
B23: Moldoveni | C23: 100 | D23: =D12/C12*100 -> 47.597949 | E23: =E12/C12*100 -> 52.402051 | F23: =F12/C12*100 -> 42.639952 | G23: =G12/C12*100 -> 57.360048
B24: Români | C24: 100 | D24: =D13/C13*100 -> 48.210894 | E24: =E13/C13*100 -> 51.789106 | F24: =F13/C13*100 -> 56.837839 | G24: =G13/C13*100 -> 43.162161
B25: Ucraineni | C25: 100 | D25: =D14/C14*100 -> 42.754843 | E25: =E14/C14*100 -> 57.245157 | F25: =F14/C14*100 -> 56.808215 | G25: =G14/C14*100 -> 43.191785
B26: Ruși | C26: 100 | D26: =D15/C15*100 -> 41.821634 | E26: =E15/C15*100 -> 58.178366 | F26: =F15/C15*100 -> 80.91878 | G26: =G15/C15*100 -> 19.08122
B27: Găgăuzi | C27: 100 | D27: =D16/C16*100 -> 47.648783 | E27: =E16/C16*100 -> 52.351217 | F27: =F16/C16*100 -> 42.549252 | G27: =G16/C16*100 -> 57.450748
B28: Bulgari | C28: 100 | D28: =D17/C17*100 -> 46.233916 | E28: =E17/C17*100 -> 53.766084 | F28: =F17/C17*100 -> 59.532901 | G28: =G17/C17*100 -> 40.467099
B29: Romi/Țigani | C29: 100 | D29: =D18/C18*100 -> 47.050021 | E29: =E18/C18*100 -> 52.949979 | F29: =F18/C18*100 -> 65.979051 | G29: =G18/C18*100 -> 34.020949
B30: Alte etnii | C30: 100 | D30: =D19/C19*100 -> 51.999424 | E30: =E19/C19*100 -> 48.000576 | F30: =F19/C19*100 -> 84.220765 | G30: =G19/C19*100 -> 15.779235
B31: Nu au declarat etnia | C31: 100 | D31: =D20/C20*100 -> 48.723898 | E31: =E20/C20*100 -> 51.276102 | F31: =F20/C20*100 -> 76.566125 | G31: =G20/C20*100 -> 23.433875
B33: 1Datele se referă doar la UAT efectiv recenzate și nu includ unitățile administrativ-teritoriale din stânga Nistrului, municipiului Bender (inclusiv satul Proteagailovca), comuna Chițcani (inclusiv satele Merenești și Zahorna), satele Cremenciug și Gîsca din raionul Căușeni, comuna Corjova (inclusiv satul Mahala) din raionul Dubăsari, precum și satul Roghi din cadrul comunei Molovata Nouă, raionul Dubăsari.
B34: ² Datele pentru "Populație" sunt prezentate pentru populația cu reședință obișnuită.

Sheet 5.4
B1: Cuprins
B3: =Cuprins!B2 -> Recensământul Populației și Locuințelor 2024: CARACTERISTICI ETNO-CULTURALE
B5: 5.4 Populația după etnie pe regiuni de dezvoltare și raioane/municipii, la recensământul din 20241,2
M6: persoane
B7: Cod statistic CUATM | C7: Regiuni de dezvoltare și raioane/municipii | D7: Total | E7: Etnia declarată | M7: Nu au declarat etnia
E8: Moldoveni | F8: Români | G8: Ucraineni | H8: Ruși | I8: Găgăuzi | J8: Bulgari | K8: Romi/Țigani | L8: Alte etnii
B9: A | C9: B | D9: 1 | E9: 2 | F9: 3 | G9: 4 | H9: 5 | I9: 6 | J9: 7 | K9: 8 | L9: 9 | M9: 10
C10: Total | D10: 2409207 | E10: 1848670 | F10: 193197 | G10: 123586 | H10: 81630 | I10: 97205 | J10: 38236 | K10: 9356 | L10: 13879 | M10: 3448
B11: 100000 | C11: Mun. Chişinău | D11: 720128 | E11: 521837 | F11: 92988 | G11: 38701 | H11: 42796 | I11: 5590 | J11: 6505 | K11: 789 | L11: 8933 | M11: 1989
C12: Nord | D12: 608651 | E12: 495145 | F12: 23224 | G12: 59118 | H12: 22096 | I12: 471 | J12: 451 | K12: 5426 | L12: 2114 | M12: 606
B13: 0300000 | C13: Mun. Bălţi | D13: 94546 | E13: 67259 | F13: 3521 | G13: 12445 | H13: 9537 | I13: 115 | J13: 136 | K13: 144 | L13: 1085 | M13: 304
B14: 1400000 | C14: Briceni | D14: 46894 | E14: 36157 | F14: 1369 | G14: 8161 | H14: 823 | I14: 32 | J14: 26 | K14: 210 | L14: 98 | M14: 18
B15: 3400000 | C15: Donduşeni | D15: 28108 | E15: 22800 | F15: 1313 | G15: 2322 | H15: 1452 | I15: 16 | J15: 23 | K15: 124 | L15: 46 | M15: 12
B16: 3600000 | C16: Drochia | D16: 53738 | E16: 47748 | F16: 1776 | G16: 3114 | H16: 629 | I16: 34 | J16: 29 | K16: 317 | L16: 85 | M16: 6
B17: 4100000 | C17: Edineţ | D17: 50429 | E17: 39051 | F17: 1680 | G17: 6704 | H17: 2073 | I17: 73 | J17: 54 | K17: 638 | L17: 136 | M17: 20
B18: 4300000 | C18: Făleşti | D18: 56039 | E18: 48445 | F18: 2497 | G18: 3726 | H18: 1129 | I18: 28 | J18: 30 | K18: 60 | L18: 94 | M18: 30
B19: 4500000 | C19: Floreşti | D19: 53264 | E19: 47150 | F19: 2118 | G19: 2081 | H19: 1649 | I19: 21 | J19: 25 | K19: 56 | L19: 77 | M19: 87
B20: 4800000 | C20: Glodeni | D20: 35829 | E20: 28591 | F20: 1757 | G20: 4214 | H20: 702 | I20: 16 | J20: 22 | K20: 370 | L20: 141 | M20: 16
B21: 6200000 | C21: Ocniţa | D21: 31610 | E21: 21946 | F21: 543 | G21: 5919 | H21: 1224 | I21: 30 | J21: 41 | K21: 1819 | L21: 59 | M21: 29
B22: 7100000 | C22: Rîşcani | D22: 43652 | E22: 33894 | F22: 1449 | G22: 6452 | H22: 921 | I22: 48 | J22: 31 | K22: 740 | L22: 98 | M22: 19
B23: 7400000 | C23: Sîngerei | D23: 55933 | E23: 49282 | F23: 2329 | G23: 2753 | H23: 1310 | I23: 37 | J23: 18 | K23: 71 | L23: 93 | M23: 40
B24: 7800000 | C24: Soroca | D24: 58609 | E24: 52822 | F24: 2872 | G24: 1227 | H24: 647 | I24: 21 | J24: 16 | K24: 877 | L24: 102 | M24: 25
C25: Centru | D25: 670088 | E25: 587027 | F25: 58061 | G25: 14281 | H25: 5490 | I25: 483 | J25: 1104 | K25: 1944 | L25: 1280 | M25: 418
B26: 1000000 | C26: Anenii Noi | D26: 57687 | E26: 48827 | F26: 3773 | G26: 2434 | H26: 1695 | I26: 147 | J26: 290 | K26: 152 | L26: 304 | M26: 65
B27: 2500000 | C27: Călăraşi | D27: 43864 | E27: 37599 | F27: 4371 | G27: 1202 | H27: 219 | I27: 19 | J27: 18 | K27: 375 | L27: 48 | M27: 13
B28: 3100000 | C28: Criuleni | D28: 52926 | E28: 45192 | F28: 5733 | G28: 1352 | H28: 415 | I28: 48 | J28: 40 | K28: 24 | L28: 99 | M28: 23
B29: 3800000 | C29: Dubăsari | D29: 21781 | E29: 20997 | F29: 540 | G29: 104 | H29: 97 | I29: 17 | J29: 4 | K29: 4 | L29: 18 | M29: -
B30: 5300000 | C30: Hînceşti | D30: 69462 | E30: 60838 | F30: 5168 | G30: 2367 | H30: 447 | I30: 52 | J30: 81 | K30: 342 | L30: 147 | M30: 20
B31: 5500000 | C31: Ialoveni | D31: 74458 | E31: 60068 | F31: 11627 | G31: 1360 | H31: 350 | I31: 43 | J31: 494 | K31: 318 | L31: 155 | M31: 43
B32: 6000000 | C32: Nisporeni | D32: 36413 | E32: 32552 | F32: 3131 | G32: 107 | H32: 73 | I32: 9 | J32: 16 | K32: 474 | L32: 27 | M32: 24
B33: 6400000 | C33: Orhei | D33: 79242 | E33: 69714 | F33: 6667 | G33: 1748 | H33: 678 | I33: 43 | J33: 45 | K33: 117 | L33: 172 | M33: 58
B34: 6700000 | C34: Rezina | D34: 30243 | E34: 27485 | F34: 1745 | G34: 564 | H34: 300 | I34: 25 | J34: 22 | K34: 22 | L34: 51 | M34: 29
B35: 8000000 | C35: Străşeni | D35: 61362 | E35: 53346 | F35: 6942 | G35: 412 | H35: 392 | I35: 37 | J35: 42 | K35: 29 | L35: 87 | M35: 75
B36: 8300000 | C36: Şoldăneşti | D36: 25394 | E36: 23770 | F36: 1170 | G36: 279 | H36: 90 | I36: 5 | J36: 7 | K36: 43 | L36: 24 | M36: 6
B37: 8900000 | C37: Teleneşti | D37: 41452 | E37: 37626 | F37: 3408 | G37: 269 | H37: 96 | I37: 5 | J37: 8 | K37: - | L37: 31 | M37: 9
B38: 9200000 | C38: Ungheni | D38: 75804 | E38: 69013 | F38: 3786 | G38: 2083 | H38: 638 | I38: 33 | J38: 37 | K38: 44 | L38: 117 | M38: 53
C39: Sud | D39: 306672 | E39: 238160 | F39: 18860 | G39: 8777 | H39: 7959 | I39: 6463 | J39: 24464 | K39: 857 | L39: 916 | M39: 216
B40: 1200000 | C40: Basarabeasca | D40: 14914 | E40: 9754 | F40: 883 | G40: 871 | H40: 1119 | I40: 1222 | J40: 777 | K40: 168 | L40: 111 | M40: 9
B41: 1700000 | C41: Cahul | D41: 72775 | E41: 58623 | F41: 3908 | G41: 2838 | H41: 2467 | I41: 1714 | J41: 2694 | K41: 79 | L41: 387 | M41: 65
B42: 2100000 | C42: Cantemir | D42: 33181 | E42: 28484 | F42: 2400 | G42: 350 | H42: 219 | I42: 191 | J42: 1460 | K42: 48 | L42: 27 | M42: 2
...

Sheet 5.5 
B1: Cuprins
B3: =Cuprins!B2 -> Recensământul Populației și Locuințelor 2024: CARACTERISTICI ETNO-CULTURALE
B5: 5.5 Populația după etnie pe regiuni de dezvoltare și raioane/municipii, la recensământul din 20241,2
M6: %
B7: Cod statistic CUATM | C7: Regiuni de dezvoltare și raioane/municipii | D7: Total | E7: Etnia declarată | M7: Nu au declarat etnia
E8: Moldoveni | F8: Români | G8: Ucraineni | H8: Ruși | I8: Găgăuzi | J8: Bulgari | K8: Romi/Țigani | L8: Alte etnii
B9: A | C9: B | D9: 1 | E9: 2 | F9: 3 | G9: 4 | H9: 5 | I9: 6 | J9: 7 | K9: 8 | L9: 9 | M9: 10
C10: Total | D10: 100 | E10: 76.733548 | F10: 8.0191117 | G10: 5.1297377 | H10: 3.3882518 | I10: 4.0347301 | J10: 1.5870782 | K10: 0.38834355 | L10: 0.57608167 | M10: 0.14311763
B11: 100000 | C11: Mun. Chişinău | D11: 100 | E11: 72.464479 | F11: 12.912704 | G11: 5.3741835 | H11: 5.9428324 | I11: 0.77625089 | J11: 0.90331163 | K11: 0.10956386 | L11: 1.2404739 | M11: 0.2762009
C12: Nord | D12: 100 | E12: 81.351218 | F12: 3.8156513 | G12: 9.7129554 | H12: 3.6303235 | I12: 0.077384248 | J12: 0.074098293 | K12: 0.89147968 | L12: 0.34732548 | M12: 0.099564447
B13: 0300000 | C13: Mun. Bălţi | D13: 100 | E13: 71.138917 | F13: 3.7241131 | G13: 13.162905 | H13: 10.087153 | I13: 0.12163391 | J13: 0.14384532 | K13: 0.15230681 | L13: 1.1475895 | M13: 0.32153661
B14: 1400000 | C14: Briceni | D14: 100 | E14: 77.103681 | F14: 2.91935 | G14: 17.403079 | H14: 1.755022 | I14: 0.068239007 | J14: 0.055444193 | K14: 0.44781848 | L14: 0.20898196 | M14: 0.038384442
B15: 3400000 | C15: Donduşeni | D15: 100 | E15: 81.115697 | F15: 4.671268 | G15: 8.2609933 | H15: 5.1657891 | I15: 0.056923296 | J15: 0.081827238 | K15: 0.44115554 | L15: 0.16365448 | M15: 0.042692472
B16: 3600000 | C16: Drochia | D16: 100 | E16: 88.853325 | F16: 3.3049239 | G16: 5.7947821 | H16: 1.1704939 | I16: 0.063269939 | J16: 0.053965536 | K16: 0.58989914 | L16: 0.15817485 | M16: 0.011165283
B17: 4100000 | C17: Edineţ | D17: 100 | E17: 77.437586 | F17: 3.3314164 | G17: 13.293938 | H17: 4.1107299 | I17: 0.14475798 | J17: 0.10708124 | K17: 1.2651451 | L17: 0.26968609 | M17: 0.03965972
B18: 4300000 | C18: Făleşti | D18: 100 | E18: 86.448723 | F18: 4.4558254 | G18: 6.6489409 | H18: 2.0146684 | I18: 0.049965203 | J18: 0.053534146 | K18: 0.10706829 | L18: 0.16774032 | M18: 0.053534146
B19: 4500000 | C19: Floreşti | D19: 100 | E19: 88.521328 | F19: 3.9764193 | G19: 3.906954 | H19: 3.0958997 | I19: 0.039426254 | J19: 0.046936017 | K19: 0.10513668 | L19: 0.14456293 | M19: 0.16333734
B20: 4800000 | C20: Glodeni | D20: 100 | E20: 79.798487 | F20: 4.9038488 | G20: 11.761422 | H20: 1.9593067 | I20: 0.044656563 | J20: 0.061402774 | K20: 1.032683 | L20: 0.39353596 | M20: 0.044656563
B21: 6200000 | C21: Ocniţa | D21: 100 | E21: 69.427396 | F21: 1.7178108 | G21: 18.725087 | H21: 3.8721923 | I21: 0.094906675 | J21: 0.12970579 | K21: 5.7545081 | L21: 0.18664979 | M21: 0.091743119
B22: 7100000 | C22: Rîşcani | D22: 100 | E22: 77.645927 | F22: 3.3194355 | G22: 14.780537 | H22: 2.109869 | I22: 0.1099606 | J22: 0.071016219 | K22: 1.6952259 | L22: 0.22450289 | M22: 0.04352607
B23: 7400000 | C23: Sîngerei | D23: 100 | E23: 88.108988 | F23: 4.1639104 | G23: 4.9219602 | H23: 2.3420879 | I23: 0.066150573 | J23: 0.03218136 | K23: 0.12693759 | L23: 0.16627036 | M23: 0.071514133
B24: 7800000 | C24: Soroca | D24: 100 | E24: 90.12609 | F24: 4.9002713 | G24: 2.0935351 | H24: 1.103926 | I24: 0.035830674 | J24: 0.027299562 | K24: 1.4963572 | L24: 0.1740347 | M24: 0.042655565
C25: Centru | D25: 100 | E25: 87.604464 | F25: 8.6646828 | G25: 2.1312126 | H25: 0.81929538 | I25: 0.072080085 | J25: 0.16475448 | K25: 0.29011115 | L25: 0.19101969 | M25: 0.062379867
B26: 1000000 | C26: Anenii Noi | D26: 100 | E26: 84.641254 | F26: 6.5404684 | G26: 4.2193215 | H26: 2.9382703 | I26: 0.25482344 | J26: 0.50271292 | K26: 0.26349091 | L26: 0.52698182 | M26: 0.11267703
B27: 2500000 | C27: Călăraşi | D27: 100 | E27: 85.717217 | F27: 9.9648915 | G27: 2.7402882 | H27: 0.49927047 | I27: 0.043315703 | J27: 0.041035929 | K27: 0.85491519 | L27: 0.10942914 | M27: 0.02963706
B28: 3100000 | C28: Criuleni | D28: 100 | E28: 85.387144 | F28: 10.832105 | G28: 2.5545101 | H28: 0.78411367 | I28: 0.090692665 | J28: 0.075577221 | K28: 0.045346333 | L28: 0.18705362 | M28: 0.043456902
B29: 3800000 | C29: Dubăsari | D29: 100 | E29: 96.400533 | F29: 2.479225 | G29: 0.47748037 | H29: 0.44534227 | I29: 0.078049676 | J29: 0.01836463 | K29: 0.01836463 | L29: 0.082640834 | M29: -
B30: 5300000 | C30: Hînceşti | D30: 100 | E30: 87.584579 | F30: 7.4400392 | G30: 3.4076186 | H30: 0.64351732 | I30: 0.074861075 | J30: 0.11661052 | K30: 0.49235553 | L30: 0.2116265 | M30: 0.028792721
B31: 5500000 | C31: Ialoveni | D31: 100 | E31: 80.673668 | F31: 15.615515 | G31: 1.8265331 | H31: 0.47006366 | I31: 0.057750678 | J31: 0.66346128 | K31: 0.42708641 | L31: 0.20817105 | M31: 0.057750678
B32: 6000000 | C32: Nisporeni | D32: 100 | E32: 89.396644 | F32: 8.5985774 | G32: 0.2938511 | H32: 0.20047785 | I32: 0.024716447 | J32: 0.043940351 | K32: 1.3017329 | L32: 0.074149342 | M32: 0.065910526
B33: 6400000 | C33: Orhei | D33: 100 | E33: 87.976073 | F33: 8.4134676 | G33: 2.2059009 | H33: 0.85560688 | I33: 0.054264153 | J33: 0.056788067 | K33: 0.14764897 | L33: 0.21705661 | M33: 0.073193508
B34: 6700000 | C34: Rezina | D34: 100 | E34: 90.880534 | F34: 5.7699302 | G34: 1.8648944 | H34: 0.99196508 | I34: 0.082663757 | J34: 0.072744106 | K34: 0.072744106 | L34: 0.16863406 | M34: 0.095889958
B35: 8000000 | C35: Străşeni | D35: 100 | E35: 86.936541 | F35: 11.313191 | G35: 0.67142531 | H35: 0.63883185 | I35: 0.060297904 | J35: 0.06844627 | K35: 0.04726052 | L35: 0.14178156 | M35: 0.12222548
B36: 8300000 | C36: Şoldăneşti | D36: 100 | E36: 93.604789 | F36: 4.6073876 | G36: 1.0986847 | H36: 0.35441443 | I36: 0.01968969 | J36: 0.027565567 | K36: 0.16933134 | L36: 0.094510514 | M36: 0.023627629
B37: 8900000 | C37: Teleneşti | D37: 100 | E37: 90.770047 | F37: 8.2215575 | G37: 0.64894336 | H37: 0.23159317 | I37: 0.012062144 | J37: 0.019299431 | K37: - | L37: 0.074785294 | M37: 0.02171186
B38: 9200000 | C38: Ungheni | D38: 100 | E38: 91.04137 | F38: 4.9944594 | G38: 2.7478761 | H38: 0.84164424 | I38: 0.043533323 | J38: 0.048810089 | K38: 0.05804443 | L38: 0.15434542 | M38: 0.069917155
C39: Sud | D39: 100 | E39: 77.659519 | F39: 6.149893 | G39: 2.8620154 | H39: 2.595281 | I39: 2.1074633 | J39: 7.9772526 | K39: 0.27945166 | L39: 0.29869046 | M39: 0.070433558
B40: 1200000 | C40: Basarabeasca | D40: 100 | E40: 65.401636 | F40: 5.9206115 | G40: 5.8401502 | H40: 7.5030173 | I40: 8.1936436 | J40: 5.2098699 | K40: 1.1264584 | L40: 0.74426713 | M40: 0.060345984
B41: 1700000 | C41: Cahul | D41: 100 | E41: 80.553762 | F41: 5.369976 | G41: 3.8996908 | H41: 3.3899004 | I41: 2.3552044 | J41: 3.7018207 | K41: 0.10855376 | L41: 0.53177602 | M41: 0.089316386
B42: 2100000 | C42: Cantemir | D42: 100 | E42: 85.844308 | F42: 7.2330551 | G42: 1.0548205 | H42: 0.66001627 | I42: 0.57563063 | J42: 4.4001085 | K42: 0.1446611 | L42: 0.081371869 | M42: 0.0060275459
...

Sheet  5.6
B1: Cuprins
B3: =Cuprins!B2 -> Recensământul Populației și Locuințelor 2024: CARACTERISTICI ETNO-CULTURALE
B5: 5.6 Populația după etnie pe orașe (municipii) și sate (comune), la recensământul din 20241,2
M6: persoane
B7: Cod statistic CUATM | C7: Regiuni de dezvoltare, raioane/municipii și orașe/sate (comune) | D7: Total | E7: Etnia declarată | M7: Nu au declarat etnia
E8: Moldoveni | F8: Români | G8: Ucraineni | H8: Ruși | I8: Găgăuzi | J8: Bulgari | K8: Romi/Țigani | L8: Alte etnii
B9: A | C9: B | D9: 1 | E9: 2 | F9: 3 | G9: 4 | H9: 5 | I9: 6 | J9: 7 | K9: 8 | L9: 9 | M9: 10
C10: Total | D10: 2409207 | E10: 1848670 | F10: 193197 | G10: 123586 | H10: 81630 | I10: 97205 | J10: 38236 | K10: 9356 | L10: 13879 | M10: 3448
B11: 100000 | C11: Mun. Chișinău | D11: 720128 | E11: 521837 | F11: 92988 | G11: 38701 | H11: 42796 | I11: 5590 | J11: 6505 | K11: 789 | L11: 8933 | M11: 1989
B12: 101000 | C12: or. Chișinău, din care pe sectoare | D12: 567038 | E12: 399844 | F12: 69857 | G12: 35715 | H12: 39960 | I12: 5051 | J12: 5934 | K12: 650 | L12: 8276 | M12: 1751
B13: 110000 | C13: Botanica | D13: 144824 | E13: 103397 | F13: 12485 | G13: 10369 | H13: 12794 | I13: 1521 | J13: 1789 | K13: 106 | L13: 1933 | M13: 430
B14: 120000 | C14: Buiucani | D14: 100985 | E14: 71790 | F14: 14519 | G14: 5326 | H14: 6228 | I14: 772 | J14: 841 | K14: 127 | L14: 1158 | M14: 224
B15: 130000 | C15: Centru | D15: 87230 | E15: 58604 | F15: 13041 | G15: 5573 | H15: 5226 | I15: 820 | J15: 857 | K15: 203 | L15: 2495 | M15: 411
B16: 140000 | C16: Ciocana | D16: 105680 | E16: 79494 | F16: 12344 | G16: 5447 | H16: 5523 | I16: 693 | J16: 941 | K16: 89 | L16: 890 | M16: 259
B17: 150000 | C17: Rîșcani | D17: 128319 | E17: 86559 | F17: 17468 | G17: 9000 | H17: 10189 | I17: 1245 | J17: 1506 | K17: 125 | L17: 1800 | M17: 427
B18: 111000 | C18: or. Sîngera | D18: 12368 | E18: 11171 | F18: 937 | G18: 80 | H18: 105 | I18: 36 | J18: 13 | K18: 1 | L18: 22 | M18: 3
B19: 121000 | C19: or. Durlești | D19: 26308 | E19: 20324 | F19: 4650 | G19: 449 | H19: 450 | I19: 123 | J19: 134 | K19: 40 | L19: 110 | M19: 28
B20: 122000 | C20: or. Vatra | D20: 3391 | E20: 2376 | F20: 473 | G20: 148 | H20: 232 | I20: 15 | J20: 25 | K20: 50 | L20: 42 | M20: 30
B21: 131000 | C21: or. Codru | D21: 18310 | E21: 12470 | F21: 4245 | G21: 679 | H21: 509 | I21: 113 | J21: 103 | K21: 10 | L21: 126 | M21: 55
B22: 141000 | C22: or. Vadul lui Vodă | D22: 4280 | E22: 3475 | F22: 330 | G22: 152 | H22: 278 | I22: 6 | J22: 11 | K22: - | L22: 23 | M22: 5
B23: 151000 | C23: or. Cricova | D23: 9536 | E23: 7868 | F23: 858 | G23: 276 | H23: 359 | I23: 39 | J23: 56 | K23: 13 | L23: 56 | M23: 11
B24: 112000 | C24: Băcioi | D24: 11663 | E24: 10591 | F24: 987 | G24: 27 | H24: 26 | I24: 3 | J24: 11 | K24: 6 | L24: 11 | M24: 1
B25: 123000 | C25: Condriţa | D25: 547 | E25: 465 | F25: 72 | G25: 4 | H25: 1 | I25: 1 | J25: - | K25: - | L25: 4 | M25: -
B26: 125000 | C26: Ghidighici | D26: 5240 | E26: 4157 | F26: 958 | G26: 56 | H26: 37 | I26: 6 | J26: 7 | K26: - | L26: 11 | M26: 8
B27: 126000 | C27: Truşeni | D27: 10937 | E27: 8452 | F27: 2152 | G27: 110 | H27: 94 | I27: 24 | J27: 43 | K27: - | L27: 36 | M27: 26
B28: 142000 | C28: Bubuieci | D28: 11152 | E28: 9307 | F28: 1423 | G28: 117 | H28: 162 | I28: 39 | J28: 44 | K28: 14 | L28: 40 | M28: 6
B29: 143000 | C29: Budeşti | D29: 4425 | E29: 3990 | F29: 320 | G29: 41 | H29: 32 | I29: 5 | J29: 12 | K29: - | L29: 21 | M29: 4
B30: 144000 | C30: Coloniţa | D30: 3956 | E30: 3200 | F30: 647 | G30: 31 | H30: 53 | I30: 11 | J30: 5 | K30: 1 | L30: 7 | M30: 1
B31: 145000 | C31: Cruzeşti | D31: 1709 | E31: 1473 | F31: 194 | G31: 17 | H31: 15 | I31: 3 | J31: 1 | K31: - | L31: 6 | M31: -
B32: 146000 | C32: Tohatin | D32: 4045 | E32: 3169 | F32: 636 | G32: 89 | H32: 68 | I32: 20 | J32: 16 | K32: - | L32: 20 | M32: 27
B33: 152000 | C33: Ciorescu | D33: 6714 | E33: 5535 | F33: 645 | G33: 268 | H33: 171 | I33: 36 | J33: 26 | K33: 2 | L33: 31 | M33: -
B34: 153000 | C34: Grătieşti | D34: 7299 | E34: 5971 | F34: 1172 | G34: 57 | H34: 48 | I34: 10 | J34: 11 | K34: 1 | L34: 22 | M34: 7
B35: 154000 | C35: Stăuceni | D35: 11210 | E35: 7999 | F35: 2432 | G35: 385 | H35: 196 | I35: 49 | J35: 53 | K35: 1 | L35: 69 | M35: 26
C36: Regiunea Nord | D36: 608651 | E36: 495145 | F36: 23224 | G36: 59118 | H36: 22096 | I36: 471 | J36: 451 | K36: 5426 | L36: 2114 | M36: 606
B37: 300000 | C37: Mun. Bălți | D37: 94546 | E37: 67259 | F37: 3521 | G37: 12445 | H37: 9537 | I37: 115 | J37: 136 | K37: 144 | L37: 1085 | M37: 304
B38: 301000 | C38: or. Bălți | D38: 90954 | E38: 64349 | F38: 3257 | G38: 12156 | H38: 9428 | I38: 114 | J38: 136 | K38: 144 | L38: 1067 | M38: 303
B39: 310000 | C39: Elizaveta | D39: 2620 | E39: 2354 | F39: 249 | G39: 9 | H39: 8 | I39: - | J39: - | K39: - | L39: - | M39: -
B40: 311000 | C40: Sadovoe | D40: 972 | E40: 556 | F40: 15 | G40: 280 | H40: 101 | I40: 1 | J40: - | K40: - | L40: 18 | M40: 1
B41: 1400000 | C41: Raionul Briceni | D41: 46894 | E41: 36157 | F41: 1369 | G41: 8161 | H41: 823 | I41: 32 | J41: 26 | K41: 210 | L41: 98 | M41: 18
B42: 1401000 | C42: or. Briceni | D42: 5785 | E42: 3563 | F42: 128 | G42: 1562 | H42: 298 | I42: 13 | J42: 13 | K42: 172 | L42: 33 | M42: 3
...

Sheet 5.7
B1: Cuprins
B3: =Cuprins!B2 -> Recensământul Populației și Locuințelor 2024: CARACTERISTICI ETNO-CULTURALE
B5: 5.7 Populația după etnie pe orașe (municipii) și sate (comune), la recensământul din 20241,2
M6: %
B7: Cod statistic CUATM | C7: Regiuni de dezvoltare, raioane/municipii și orașe/sate (comune) | D7: Total | E7: Etnia declarată | M7: Nu au declarat etnia
E8: Moldoveni | F8: Români | G8: Ucraineni | H8: Ruși | I8: Găgăuzi | J8: Bulgari | K8: Romi/ Țigani | L8: Alte etnii
B9: A | C9: B | D9: 1 | E9: 2 | F9: 3 | G9: 4 | H9: 5 | I9: 6 | J9: 7 | K9: 8 | L9: 9 | M9: 10
C10: Total | D10: 100 | E10: 76.733548 | F10: 8.0191117 | G10: 5.1297377 | H10: 3.3882518 | I10: 4.0347301 | J10: 1.5870782 | K10: 0.38834355 | L10: 0.57608167 | M10: 0.14311763
B11: 100000 | C11: Mun. Chișinău | D11: 100 | E11: 72.464479 | F11: 12.912704 | G11: 5.3741835 | H11: 5.9428324 | I11: 0.77625089 | J11: 0.90331163 | K11: 0.10956386 | L11: 1.2404739 | M11: 0.2762009
B12: 101000 | C12: or. Chișinău, din care pe sectoare | D12: 100 | E12: 70.514498 | F12: 12.319633 | G12: 6.2985197 | H12: 7.0471468 | I12: 0.89076923 | J12: 1.0464907 | K12: 0.11463077 | L12: 1.4595142 | M12: 0.30879765
B13: 110000 | C13: Botanica | D13: 100 | E13: 71.394935 | F13: 8.6208087 | G13: 7.1597249 | H13: 8.8341711 | I13: 1.0502403 | J13: 1.2352925 | K13: 0.073192289 | L13: 1.3347235 | M13: 0.29691211
B14: 120000 | C14: Buiucani | D14: 100 | E14: 71.089766 | F14: 14.377383 | G14: 5.2740506 | H14: 6.1672526 | I14: 0.76446997 | J14: 0.83279695 | K14: 0.12576125 | L14: 1.146705 | M14: 0.22181512
B15: 130000 | C15: Centru | D15: 100 | E15: 67.183308 | F15: 14.950132 | G15: 6.388857 | H15: 5.9910581 | I15: 0.94004356 | J15: 0.98246016 | K15: 0.2327181 | L15: 2.8602545 | M15: 0.47116818
B16: 140000 | C16: Ciocana | D16: 100 | E16: 75.221423 | F16: 11.680545 | G16: 5.1542392 | H16: 5.2261544 | I16: 0.65575322 | J16: 0.89042392 | K16: 0.084216503 | L16: 0.84216503 | M16: 0.24507949
B17: 150000 | C17: Rîșcani | D17: 100 | E17: 67.456105 | F17: 13.612949 | G17: 7.0137704 | H17: 7.9403674 | I17: 0.97023823 | J17: 1.1736376 | K17: 0.097413477 | L17: 1.4027541 | M17: 0.33276444
B18: 111000 | C18: or. Sîngera | D18: 100 | E18: 90.321798 | F18: 7.5760026 | G18: 0.64683053 | H18: 0.84896507 | I18: 0.29107374 | J18: 0.10510996 | K18: 0.0080853816 | L18: 0.1778784 | M18: 0.024256145
B19: 121000 | C19: or. Durlești | D19: 100 | E19: 77.254067 | F19: 17.675232 | G19: 1.7067052 | H19: 1.7105063 | I19: 0.46753839 | J19: 0.50935077 | K19: 0.15204501 | L19: 0.41812376 | M19: 0.1064315
B20: 122000 | C20: or. Vatra | D20: 100 | E20: 70.067827 | F20: 13.948688 | G20: 4.3644942 | H20: 6.8416396 | I20: 0.44234739 | J20: 0.73724565 | K20: 1.4744913 | L20: 1.2385727 | M20: 0.88469478
B21: 131000 | C21: or. Codru | D21: 100 | E21: 68.104861 | F21: 23.184052 | G21: 3.7083561 | H21: 2.7799017 | I21: 0.6171491 | J21: 0.56253413 | K21: 0.054614965 | L21: 0.68814855 | M21: 0.3003823
B22: 141000 | C22: or. Vadul lui Vodă | D22: 100 | E22: 81.191589 | F22: 7.7102804 | G22: 3.5514019 | H22: 6.4953271 | I22: 0.14018692 | J22: 0.25700935 | K22: - | L22: 0.53738318 | M22: 0.11682243
B23: 151000 | C23: or. Cricova | D23: 100 | E23: 82.508389 | F23: 8.9974832 | G23: 2.8942953 | H23: 3.7646812 | I23: 0.40897651 | J23: 0.58724832 | K23: 0.1363255 | L23: 0.58724832 | M23: 0.11535235
B24: 112000 | C24: Băcioi | D24: 100 | E24: 90.80854 | F24: 8.4626597 | G24: 0.23150133 | H24: 0.22292721 | I24: 0.02572237 | J24: 0.094315356 | K24: 0.05144474 | L24: 0.094315356 | M24: 0.0085741233
B25: 123000 | C25: Condriţa | D25: 100 | E25: 85.009141 | F25: 13.162706 | G25: 0.73126143 | H25: 0.18281536 | I25: 0.18281536 | J25: - | K25: - | L25: 0.73126143 | M25: -
B26: 125000 | C26: Ghidighici | D26: 100 | E26: 79.332061 | F26: 18.282443 | G26: 1.0687023 | H26: 0.70610687 | I26: 0.11450382 | J26: 0.13358779 | K26: - | L26: 0.20992366 | M26: 0.15267176
B27: 126000 | C27: Truşeni | D27: 100 | E27: 77.278961 | F27: 19.676328 | G27: 1.0057603 | H27: 0.85946786 | I27: 0.2194386 | J27: 0.39316083 | K27: - | L27: 0.3291579 | M27: 0.23772515
B28: 142000 | C28: Bubuieci | D28: 100 | E28: 83.455882 | F28: 12.760043 | G28: 1.0491392 | H28: 1.4526542 | I28: 0.34971306 | J28: 0.39454806 | K28: 0.12553802 | L28: 0.35868006 | M28: 0.053802009
B29: 143000 | C29: Budeşti | D29: 100 | E29: 90.169492 | F29: 7.2316384 | G29: 0.92655367 | H29: 0.72316384 | I29: 0.11299435 | J29: 0.27118644 | K29: - | L29: 0.47457627 | M29: 0.09039548
B30: 144000 | C30: Coloniţa | D30: 100 | E30: 80.889788 | F30: 16.354904 | G30: 0.78361982 | H30: 1.3397371 | I30: 0.27805865 | J30: 0.12639029 | K30: 0.025278059 | L30: 0.17694641 | M30: 0.025278059
B31: 145000 | C31: Cruzeşti | D31: 100 | E31: 86.190755 | F31: 11.351668 | G31: 0.99473376 | H31: 0.87770626 | I31: 0.17554125 | J31: 0.058513751 | K31: - | L31: 0.3510825 | M31: -
B32: 146000 | C32: Tohatin | D32: 100 | E32: 78.343634 | F32: 15.723115 | G32: 2.2002472 | H32: 1.6810878 | I32: 0.49443758 | J32: 0.39555006 | K32: - | L32: 0.49443758 | M32: 0.66749073
B33: 152000 | C33: Ciorescu | D33: 100 | E33: 82.439678 | F33: 9.6067918 | G33: 3.9916592 | H33: 2.5469169 | I33: 0.53619303 | J33: 0.38725052 | K33: 0.029788502 | L33: 0.46172178 | M33: -
B34: 153000 | C34: Grătieşti | D34: 100 | E34: 81.805727 | F34: 16.056994 | G34: 0.78092889 | H34: 0.65762433 | I34: 0.13700507 | J34: 0.15070558 | K34: 0.013700507 | L34: 0.30141115 | M34: 0.095903548
B35: 154000 | C35: Stăuceni | D35: 100 | E35: 71.355932 | F35: 21.694915 | G35: 3.4344335 | H35: 1.7484389 | I35: 0.43710972 | J35: 0.47279215 | K35: 0.0089206066 | L35: 0.61552186 | M35: 0.23193577
C36: Regiunea Nord | D36: 100 | E36: 81.351218 | F36: 3.8156513 | G36: 9.7129554 | H36: 3.6303235 | I36: 0.077384248 | J36: 0.074098293 | K36: 0.89147968 | L36: 0.34732548 | M36: 0.099564447
B37: 300000 | C37: Mun. Bălți | D37: 100 | E37: 71.138917 | F37: 3.7241131 | G37: 13.162905 | H37: 10.087153 | I37: 0.12163391 | J37: 0.14384532 | K37: 0.15230681 | L37: 1.1475895 | M37: 0.32153661
B38: 301000 | C38: or. Bălți | D38: 100 | E38: 70.74895 | F38: 3.580931 | G38: 13.364998 | H38: 10.365679 | I38: 0.12533808 | J38: 0.14952613 | K38: 0.15832179 | L38: 1.1731205 | M38: 0.33313543
B39: 310000 | C39: Elizaveta | D39: 100 | E39: 89.847328 | F39: 9.5038168 | G39: 0.34351145 | H39: 0.30534351 | I39: - | J39: - | K39: - | L39: - | M39: -
B40: 311000 | C40: Sadovoe | D40: 100 | E40: 57.201646 | F40: 1.5432099 | G40: 28.806584 | H40: 10.390947 | I40: 0.10288066 | J40: - | K40: - | L40: 1.8518519 | M40: 0.10288066
B41: 1400000 | C41: Raionul Briceni | D41: 100 | E41: 77.103681 | F41: 2.91935 | G41: 17.403079 | H41: 1.755022 | I41: 0.068239007 | J41: 0.055444193 | K41: 0.44781848 | L41: 0.20898196 | M41: 0.038384442
B42: 1401000 | C42: or. Briceni | D42: 100 | E42: 61.59032 | F42: 2.2126188 | G42: 27.000864 | H42: 5.1512532 | I42: 0.2247191 | J42: 0.2247191 | K42: 2.9732066 | L42: 0.5704408 | M42: 0.051858254
...

Sheet 5.8
B1: Cuprins
B3: =Cuprins!B2 -> Recensământul Populației și Locuințelor 2024: CARACTERISTICI ETNO-CULTURALE
B5: 5.8 Populația după prima și a doua etnie declarată la recensământul din 20241,2
X6: persoane
B7: Etnia declarată3 | D7: A doua etnie declarată | Y7: Nu a declarat a doua etnie
D8: Moldovean | E8: Român | F8: Ucrainean | G8: Rus | H8: Găgăuz | I8: Bulgar | J8: Rom / Țigan | K8: Evreu | L8: German / Neamț | M8: Polonez | N8: Belorus | O8: Armean | P8: Azer | Q8: Turc | R8: Tătar | S8: Gruzin / Georgian | T8: Grec | U8: Ceh | V8: Italian | W8: Arab | X8: Alte etnii
B9: A | C9: 1 | D9: 2 | E9: 3 | F9: 4 | G9: 5 | H9: 6 | I9: 7 | J9: 8 | K9: 9 | L9: 10 | M9: 11 | N9: 12 | O9: 13 | P9: 14 | Q9: 15 | R9: 16 | S9: 17 | T9: 18 | U9: 19 | V9: 20 | W9: 21 | X9: 22 | Y9: 23
B10: Total | C10: 2409207 | D10: 33432 | E10: 138513 | F10: 4320 | G10: 8594 | H10: 813 | I10: 1506 | J10: 778 | K10: 266 | L10: 157 | M10: 187 | N10: 128 | O10: 78 | P10: 53 | Q10: 233 | R10: 39 | S10: 32 | T10: 80 | U10: 32 | V10: 577 | W10: 69 | X10: 1177 | Y10: 2218143
B11: Moldovean | C11: 1848670 | D11: - | E11: 137234 | F11: 3020 | G11: 5790 | H11: 389 | I11: 929 | J11: 653 | K11: 123 | L11: 102 | M11: 75 | N11: 83 | O11: 53 | P11: 32 | Q11: 191 | R11: 12 | S11: 23 | T11: 50 | U11: 21 | V11: 490 | W11: 53 | X11: 877 | Y11: 1698470
B12: Român | C12: 193197 | D12: 22608 | E12: - | F12: 222 | G12: 258 | H12: 18 | I12: 60 | J12: 15 | K12: 23 | L12: 23 | M12: 16 | N12: - | O12: 2 | P12: - | Q12: 15 | R12: 2 | S12: 1 | T12: 8 | U12: 3 | V12: 76 | W12: 6 | X12: 182 | Y12: 169659
B13: Ucrainean | C13: 123586 | D13: 4136 | E13: 581 | F13: - | G13: 1006 | H13: 74 | I13: 109 | J13: 95 | K13: 37 | L13: 12 | M13: 39 | N13: 17 | O13: 10 | P13: 14 | Q13: 3 | R13: 5 | S13: - | T13: 7 | U13: 4 | V13: 2 | W13: - | X13: 39 | Y13: 117396
B14: Rus | C14: 81630 | D14: 3877 | E14: 299 | F14: 721 | G14: - | H14: 145 | I14: 119 | J14: 8 | K14: 66 | L14: 16 | M14: 41 | N14: 22 | O14: 8 | P14: 5 | Q14: 8 | R14: 16 | S14: 7 | T14: 7 | U14: 4 | V14: 8 | W14: 3 | X14: 48 | Y14: 76202
B15: Găgăuz | C15: 97205 | D15: 560 | E15: 109 | F15: 70 | G15: 1132 | H15: - | I15: 277 | J15: 5 | K15: 3 | L15: 1 | M15: 2 | N15: 1 | O15: - | P15: 1 | Q15: 15 | R15: - | S15: 1 | T15: 4 | U15: - | V15: - | W15: - | X15: 6 | Y15: 95018
B16: Bulgar | C16: 38236 | D16: 802 | E16: 142 | F16: 90 | G16: 241 | H16: 143 | I16: - | J16: 2 | K16: 5 | L16: - | M16: 5 | N16: 4 | O16: 2 | P16: 1 | Q16: 1 | R16: 1 | S16: - | T16: 1 | U16: - | V16: - | W16: 3 | X16: 6 | Y16: 36787
B17: Rom / Țigan | C17: 9356 | D17: 578 | E17: 39 | F17: 78 | G17: 28 | H17: 10 | I17: 4 | J17: - | K17: 5 | L17: 1 | M17: - | N17: - | O17: 1 | P17: - | Q17: - | R17: - | S17: - | T17: - | U17: - | V17: - | W17: - | X17: 1 | Y17: 8611
B18: Evreu | C18: 1640 | D18: 90 | E18: 15 | F18: 23 | G18: 34 | H18: 1 | I18: - | J18: - | K18: - | L18: - | M18: 3 | N18: - | O18: - | P18: - | Q18: - | R18: - | S18: - | T18: - | U18: - | V18: - | W18: - | X18: 2 | Y18: 1472
B19: German / Neamț | C19: 763 | D19: 48 | E19: 5 | F19: 2 | G19: 14 | H19: 2 | I19: 1 | J19: - | K19: - | L19: - | M19: - | N19: - | O19: - | P19: - | Q19: - | R19: - | S19: - | T19: - | U19: - | V19: - | W19: 1 | X19: 1 | Y19: 689
B20: Polonez | C20: 1184 | D20: 70 | E20: 12 | F20: 30 | G20: 14 | H20: 2 | I20: 1 | J20: - | K20: 2 | L20: - | M20: - | N20: 1 | O20: - | P20: - | Q20: - | R20: 1 | S20: - | T20: - | U20: - | V20: - | W20: - | X20: 4 | Y20: 1047
B21: Belorus | C21: 2143 | D21: 129 | E21: 8 | F21: 16 | G21: 20 | H21: 4 | I21: 2 | J21: - | K21: - | L21: - | M21: 2 | N21: - | O21: 1 | P21: - | Q21: - | R21: - | S21: - | T21: - | U21: - | V21: 1 | W21: - | X21: 2 | Y21: 1958
B22: Armean | C22: 958 | D22: 72 | E22: 5 | F22: 13 | G22: 12 | H22: - | I22: 1 | J22: - | K22: 1 | L22: - | M22: 2 | N22: - | O22: - | P22: - | Q22: - | R22: - | S22: - | T22: 1 | U22: - | V22: - | W22: - | X22: 2 | Y22: 849
B23: Azer | C23: 708 | D23: 51 | E23: 4 | F23: 21 | G23: 7 | H23: 1 | I23: 1 | J23: - | K23: - | L23: - | M23: - | N23: - | O23: - | P23: - | Q23: - | R23: - | S23: - | T23: - | U23: - | V23: - | W23: - | X23: 1 | Y23: 622
B24: Turc | C24: 799 | D24: 77 | E24: 8 | F24: - | G24: 1 | H24: 15 | I24: - | J24: - | K24: - | L24: - | M24: 1 | N24: - | O24: - | P24: - | Q24: - | R24: 1 | S24: - | T24: - | U24: - | V24: - | W24: 1 | X24: 2 | Y24: 693
B25: Tătar | C25: 417 | D25: 25 | E25: - | F25: 3 | G25: 12 | H25: 2 | I25: 2 | J25: - | K25: - | L25: 1 | M25: - | N25: - | O25: - | P25: - | Q25: - | R25: - | S25: - | T25: - | U25: - | V25: - | W25: - | X25: 1 | Y25: 371
B26: Gruzin / Georgian | C26: 277 | D26: 18 | E26: 3 | F26: 1 | G26: 3 | H26: 2 | I26: - | J26: - | K26: - | L26: - | M26: - | N26: - | O26: - | P26: - | Q26: - | R26: - | S26: - | T26: 1 | U26: - | V26: - | W26: - | X26: 1 | Y26: 248
B27: Grec | C27: 237 | D27: 8 | E27: 8 | F27: 1 | G27: 2 | H27: 1 | I27: - | J27: - | K27: - | L27: - | M27: - | N27: - | O27: 1 | P27: - | Q27: - | R27: - | S27: - | T27: - | U27: - | V27: - | W27: - | X27: - | Y27: 216
B28: Ceh | C28: 194 | D28: 9 | E28: 2 | F28: 1 | G28: 1 | H28: - | I28: - | J28: - | K28: - | L28: - | M28: - | N28: - | O28: - | P28: - | Q28: - | R28: - | S28: - | T28: 1 | U28: - | V28: - | W28: - | X28: - | Y28: 180
B29: Italian | C29: 282 | D29: 50 | E29: 5 | F29: - | G29: 2 | H29: - | I29: - | J29: - | K29: - | L29: - | M29: - | N29: - | O29: - | P29: - | Q29: - | R29: - | S29: - | T29: - | U29: - | V29: - | W29: - | X29: 1 | Y29: 224
B30: Arab | C30: 606 | D30: 47 | E30: 2 | F30: - | G30: - | H30: 1 | I30: - | J30: - | K30: 1 | L30: 1 | M30: - | N30: - | O30: - | P30: - | Q30: - | R30: - | S30: - | T30: - | U30: - | V30: - | W30: - | X30: 1 | Y30: 553
B31: Alte etnii | C31: 3671 | D31: 177 | E31: 32 | F31: 8 | G31: 17 | H31: 3 | I31: - | J31: - | K31: - | L31: - | M31: 1 | N31: - | O31: - | P31: - | Q31: - | R31: 1 | S31: - | T31: - | U31: - | V31: - | W31: 2 | X31: - | Y31: 3430
B32: Nu au declarat etnia | C32: 3448 | D32: - | E32: - | F32: - | G32: - | H32: - | I32: - | J32: - | K32: - | L32: - | M32: - | N32: - | O32: - | P32: - | Q32: - | R32: - | S32: - | T32: - | U32: - | V32: - | W32: - | X32: - | Y32: 3448
B33: în % față de total
B34: Total | C34: 100 | D34: =IF(D10="-","-",D10/$C10*100) -> 1.3876765 | E34: =IF(E10="-","-",E10/$C10*100) -> 5.7493192 | F34: =IF(F10="-","-",F10/$C10*100) -> 0.17931211 | G34: =IF(G10="-","-",G10/$C10*100) -> 0.35671489 | H34: =IF(H10="-","-",H10/$C10*100) -> 0.033745544 | I34: =IF(I10="-","-",I10/$C10*100) -> 0.062510195 | J34: =IF(J10="-","-",J10/$C10*100) -> 0.032292783 | K34: =IF(K10="-","-",K10/$C10*100) -> 0.011040977 | ... Y34: =IF(Y10="-","-",Y10/$C10*100) -> 92.069424
B35: Moldovean | C35: 100 | D35: =IF(D11="-","-",D11/$C11*100) -> - | E35: =IF(E11="-","-",E11/$C11*100) -> 7.4233909 | F35: =IF(F11="-","-",F11/$C11*100) -> 0.16336069 | G35: =IF(G11="-","-",G11/$C11*100) -> 0.31319814 | H35: =IF(H11="-","-",H11/$C11*100) -> 0.021042155 | I35: =IF(I11="-","-",I11/$C11*100) -> 0.050252344 | J35: =IF(J11="-","-",J11/$C11*100) -> 0.035322691 | K35: =IF(K11="-","-",K11/$C11*100) -> 0.0066534319 | ... Y35: =IF(Y11="-","-",Y11/$C11*100) -> 91.87524
B36: Român | C36: 100 | D36: =IF(D12="-","-",D12/$C12*100) -> 11.702045 | E36: =IF(E12="-","-",E12/$C12*100) -> - | F36: =IF(F12="-","-",F12/$C12*100) -> 0.11490862 | G36: =IF(G12="-","-",G12/$C12*100) -> 0.13354245 | H36: =IF(H12="-","-",H12/$C12*100) -> 0.0093169149 | I36: =IF(I12="-","-",I12/$C12*100) -> 0.031056383 | J36: =IF(J12="-","-",J12/$C12*100) -> 0.0077640957 | K36: =IF(K12="-","-",K12/$C12*100) -> 0.011904947 | ... Y36: =IF(Y12="-","-",Y12/$C12*100) -> 87.816581
B37: Ucrainean | C37: 100 | D37: =IF(D13="-","-",D13/$C13*100) -> 3.3466574 | E37: =IF(E13="-","-",E13/$C13*100) -> 0.47011797 | F37: =IF(F13="-","-",F13/$C13*100) -> - | G37: =IF(G13="-","-",G13/$C13*100) -> 0.81400806 | H37: =IF(H13="-","-",H13/$C13*100) -> 0.059877332 | I37: =IF(I13="-","-",I13/$C13*100) -> 0.088197692 | J37: =IF(J13="-","-",J13/$C13*100) -> 0.076869548 | K37: =IF(K13="-","-",K13/$C13*100) -> 0.029938666 | ... Y37: =IF(Y13="-","-",Y13/$C13*100) -> 94.991342
B38: Rus | C38: 100 | D38: =IF(D14="-","-",D14/$C14*100) -> 4.7494794 | E38: =IF(E14="-","-",E14/$C14*100) -> 0.3662869 | F38: =IF(F14="-","-",F14/$C14*100) -> 0.88325371 | G38: =IF(G14="-","-",G14/$C14*100) -> - | H38: =IF(H14="-","-",H14/$C14*100) -> 0.17763077 | I38: =IF(I14="-","-",I14/$C14*100) -> 0.14577974 | J38: =IF(J14="-","-",J14/$C14*100) -> 0.0098003185 | K38: =IF(K14="-","-",K14/$C14*100) -> 0.080852628 | ... Y38: =IF(Y14="-","-",Y14/$C14*100) -> 93.350484
B39: Găgăuz | C39: 100 | D39: =IF(D15="-","-",D15/$C15*100) -> 0.57610205 | E39: =IF(E15="-","-",E15/$C15*100) -> 0.11213415 | F39: =IF(F15="-","-",F15/$C15*100) -> 0.072012757 | G39: =IF(G15="-","-",G15/$C15*100) -> 1.1645491 | H39: =IF(H15="-","-",H15/$C15*100) -> - | I39: =IF(I15="-","-",I15/$C15*100) -> 0.28496477 | J39: =IF(J15="-","-",J15/$C15*100) -> 0.0051437683 | K39: =IF(K15="-","-",K15/$C15*100) -> 0.003086261 | ... Y39: =IF(Y15="-","-",Y15/$C15*100) -> 97.750116
B40: Bulgar | C40: 100 | D40: =IF(D16="-","-",D16/$C16*100) -> 2.0974997 | E40: =IF(E16="-","-",E16/$C16*100) -> 0.37137776 | F40: =IF(F16="-","-",F16/$C16*100) -> 0.23538027 | G40: =IF(G16="-","-",G16/$C16*100) -> 0.63029606 | H40: =IF(H16="-","-",H16/$C16*100) -> 0.3739931 | I40: =IF(I16="-","-",I16/$C16*100) -> - | J40: =IF(J16="-","-",J16/$C16*100) -> 0.0052306727 | K40: =IF(K16="-","-",K16/$C16*100) -> 0.013076682 | ... Y40: =IF(Y16="-","-",Y16/$C16*100) -> 96.210378
B41: Rom / Țigan | C41: 100 | D41: =IF(D17="-","-",D17/$C17*100) -> 6.1778538 | E41: =IF(E17="-","-",E17/$C17*100) -> 0.41684481 | F41: =IF(F17="-","-",F17/$C17*100) -> 0.83368961 | G41: =IF(G17="-","-",G17/$C17*100) -> 0.29927319 | H41: =IF(H17="-","-",H17/$C17*100) -> 0.10688328 | I41: =IF(I17="-","-",I17/$C17*100) -> 0.042753313 | J41: =IF(J17="-","-",J17/$C17*100) -> - | K41: =IF(K17="-","-",K17/$C17*100) -> 0.053441642 | ... Y41: =IF(Y17="-","-",Y17/$C17*100) -> 92.037195
B42: Evreu | C42: 100 | D42: =IF(D18="-","-",D18/$C18*100) -> 5.4878049 | E42: =IF(E18="-","-",E18/$C18*100) -> 0.91463415 | F42: =IF(F18="-","-",F18/$C18*100) -> 1.402439 | G42: =IF(G18="-","-",G18/$C18*100) -> 2.0731707 | H42: =IF(H18="-","-",H18/$C18*100) -> 0.06097561 | I42: =IF(I18="-","-",I18/$C18*100) -> - | J42: =IF(J18="-","-",J18/$C18*100) -> - | K42: =IF(K18="-","-",K18/$C18*100) -> - | ... Y42: =IF(Y18="-","-",Y18/$C18*100) -> 89.756098
...

Sheet 5.9
B1: Cuprins
B3: =Cuprins!B2 -> Recensământul Populației și Locuințelor 2024: CARACTERISTICI ETNO-CULTURALE
B5: 5.9 Populația după prima și a doua etnie declarată pe regiuni de dezvoltare, la recensământul din 20241,2
N6: persoane și %
B7: Etnia declarată3 | C7: A doua etnie declarată | D7: Total | F7: Municipiul Chisinau | H7: Regiunea Nord | J7: Regiunea Centru | L7: Regiunea Sud | N7: UTA Găgăuzia
D8: persoane | E8: % | F8: persoane | G8: % | H8: persoane | I8: % | J8: persoane | K8: % | L8: persoane | M8: % | N8: persoane | O8: %
B9: A | C9: B | D9: 1 | E9: 2 | F9: 3 | G9: 4 | H9: 5 | I9: 6 | J9: 7 | K9: 8 | L9: 9 | M9: 10 | N9: 11 | O9: 12
B10: Total | D10: 2409207 | E10: 100 | F10: 720128 | G10: 100 | H10: 608651 | I10: 100 | J10: 670088 | K10: 100 | L10: 306672 | M10: 100 | N10: 103668 | O10: 100
B11: Moldovean | C11: Nu a declarat a 2-a etnie | D11: 1698470 | E11: =IF(D11="-", "-", D11/D$10*100) -> 70.499131 | F11: 462407 | G11: =IF(F11="-", "-", F11/F$10*100) -> 64.211779 | H11: 469938 | I11: =IF(H11="-", "-", H11/H$10*100) -> 77.209764 | J11: 538345 | K11: =IF(J11="-", "-", J11/J$10*100) -> 80.339448 | L11: 221482 | M11: =IF(L11="-", "-", L11/L$10*100) -> 72.221135 | N11: 6298 | O11: =IF(N11="-", "-", N11/N$10*100) -> 6.075163
B12: Moldovean | C12: Român | D12: 137234 | E12: =IF(D12="-", "-", D12/D$10*100) -> 5.6962312 | F12: 54285 | G12: =IF(F12="-", "-", F12/F$10*100) -> 7.5382432 | H12: 21669 | I12: =IF(H12="-", "-", H12/H$10*100) -> 3.5601683 | J12: 46021 | K12: =IF(J12="-", "-", J12/J$10*100) -> 6.8679039 | L12: 15231 | M12: =IF(L12="-", "-", L12/L$10*100) -> 4.9665441 | N12: 28 | O12: =IF(N12="-", "-", N12/N$10*100) -> 0.027009299
B13: Moldovean | C13: Ucrainean | D13: 3020 | E13: =IF(D13="-", "-", D13/D$10*100) -> 0.12535245 | F13: 1185 | G13: =IF(F13="-", "-", F13/F$10*100) -> 0.16455408 | H13: 1013 | I13: =IF(H13="-", "-", H13/H$10*100) -> 0.16643364 | J13: 564 | K13: =IF(J13="-", "-", J13/J$10*100) -> 0.08416805 | L13: 245 | M13: =IF(L13="-", "-", L13/L$10*100) -> 0.079889915 | N13: 13 | O13: =IF(N13="-", "-", N13/N$10*100) -> 0.012540032
B14: Moldovean | C14: Rus | D14: 5790 | E14: =IF(D14="-", "-", D14/D$10*100) -> 0.24032804 | F14: 2248 | G14: =IF(F14="-", "-", F14/F$10*100) -> 0.31216673 | H14: 1784 | I14: =IF(H14="-", "-", H14/H$10*100) -> 0.29310722 | J14: 1064 | K14: =IF(J14="-", "-", J14/J$10*100) -> 0.15878511 | L14: 652 | M14: =IF(L14="-", "-", L14/L$10*100) -> 0.212605 | N14: 42 | O14: =IF(N14="-", "-", N14/N$10*100) -> 0.040513948
B15: Moldovean | C15: Găgăuz | D15: 389 | E15: =IF(D15="-", "-", D15/D$10*100) -> 0.016146392 | F15: 159 | G15: =IF(F15="-", "-", F15/F$10*100) -> 0.022079408 | H15: 19 | I15: =IF(H15="-", "-", H15/H$10*100) -> 0.0031216576 | J15: 26 | K15: =IF(J15="-", "-", J15/J$10*100) -> 0.0038800874 | L15: 93 | M15: =IF(L15="-", "-", L15/L$10*100) -> 0.03032556 | N15: 92 | O15: =IF(N15="-", "-", N15/N$10*100) -> 0.088744839
B16: Moldovean | C16: Bulgar | D16: 929 | E16: =IF(D16="-", "-", D16/D$10*100) -> 0.038560406 | F16: 558 | G16: =IF(F16="-", "-", F16/F$10*100) -> 0.077486225 | H16: 29 | I16: =IF(H16="-", "-", H16/H$10*100) -> 0.0047646352 | J16: 80 | K16: =IF(J16="-", "-", J16/J$10*100) -> 0.01193873 | L16: 242 | M16: =IF(L16="-", "-", L16/L$10*100) -> 0.078911671 | N16: 20 | O16: =IF(N16="-", "-", N16/N$10*100) -> 0.019292356
B17: Moldovean | C17: Rom / Țigan | D17: 653 | E17: =IF(D17="-", "-", D17/D$10*100) -> 0.027104354 | F17: 55 | G17: =IF(F17="-", "-", F17/F$10*100) -> 0.0076375311 | H17: 350 | I17: =IF(H17="-", "-", H17/H$10*100) -> 0.057504218 | J17: 221 | K17: =IF(J17="-", "-", J17/J$10*100) -> 0.032980743 | L17: 26 | M17: =IF(L17="-", "-", L17/L$10*100) -> 0.0084781134 | N17: 1 | O17: =IF(N17="-", "-", N17/N$10*100) -> 0.00096461782
B18: Moldovean | C18: Evreu | D18: 123 | E18: =IF(D18="-", "-", D18/D$10*100) -> 0.0051054144 | F18: 74 | G18: =IF(F18="-", "-", F18/F$10*100) -> 0.010275951 | H18: 16 | I18: =IF(H18="-", "-", H18/H$10*100) -> 0.0026287643 | J18: 27 | K18: =IF(J18="-", "-", J18/J$10*100) -> 0.0040293215 | L18: 5 | M18: =IF(L18="-", "-", L18/L$10*100) -> 0.0016304064 | N18: 1 | O18: =IF(N18="-", "-", N18/N$10*100) -> 0.00096461782
B19: Moldovean | C19: German / Neamț | D19: 102 | E19: =IF(D19="-", "-", D19/D$10*100) -> 0.0042337582 | F19: 62 | G19: =IF(F19="-", "-", F19/F$10*100) -> 0.0086095805 | H19: 17 | I19: =IF(H19="-", "-", H19/H$10*100) -> 0.002793062 | J19: 13 | K19: =IF(J19="-", "-", J19/J$10*100) -> 0.0019400437 | L19: 10 | M19: =IF(L19="-", "-", L19/L$10*100) -> 0.0032608129 | N19: - | O19: =IF(N19="-", "-", N19/N$10*100) -> -
B20: Moldovean | C20: Polonez | D20: 75 | E20: =IF(D20="-", "-", D20/D$10*100) -> 0.0031130575 | F20: 40 | G20: =IF(F20="-", "-", F20/F$10*100) -> 0.0055545681 | H20: 24 | I20: =IF(H20="-", "-", H20/H$10*100) -> 0.0039431464 | J20: 7 | K20: =IF(J20="-", "-", J20/J$10*100) -> 0.0010446389 | L20: 4 | M20: =IF(L20="-", "-", L20/L$10*100) -> 0.0013043251 | N20: - | O20: =IF(N20="-", "-", N20/N$10*100) -> -
B21: Moldovean | C21: Belorus | D21: 83 | E21: =IF(D21="-", "-", D21/D$10*100) -> 0.003445117 | F21: 50 | G21: =IF(F21="-", "-", F21/F$10*100) -> 0.0069432101 | H21: 15 | I21: =IF(H21="-", "-", H21/H$10*100) -> 0.0024644665 | J21: 15 | K21: =IF(J21="-", "-", J21/J$10*100) -> 0.002238512 | L21: 2 | M21: =IF(L21="-", "-", L21/L$10*100) -> 0.00065216257 | N21: 1 | O21: =IF(N21="-", "-", N21/N$10*100) -> 0.00096461782
B22: Moldovean | C22: Armean | D22: 53 | E22: =IF(D22="-", "-", D22/D$10*100) -> 0.002199894 | F22: 23 | G22: =IF(F22="-", "-", F22/F$10*100) -> 0.0031938766 | H22: 7 | I22: =IF(H22="-", "-", H22/H$10*100) -> 0.0011500844 | J22: 15 | K22: =IF(J22="-", "-", J22/J$10*100) -> 0.002238512 | L22: 7 | M22: =IF(L22="-", "-", L22/L$10*100) -> 0.002282569 | N22: 1 | O22: =IF(N22="-", "-", N22/N$10*100) -> 0.00096461782
B23: Moldovean | C23: Azer | D23: 32 | E23: =IF(D23="-", "-", D23/D$10*100) -> 0.0013282379 | F23: 17 | G23: =IF(F23="-", "-", F23/F$10*100) -> 0.0023606914 | H23: 8 | I23: =IF(H23="-", "-", H23/H$10*100) -> 0.0013143821 | J23: 7 | K23: =IF(J23="-", "-", J23/J$10*100) -> 0.0010446389 | L23: - | M23: =IF(L23="-", "-", L23/L$10*100) -> - | N23: - | O23: =IF(N23="-", "-", N23/N$10*100) -> -
B24: Moldovean | C24: Turc | D24: 191 | E24: =IF(D24="-", "-", D24/D$10*100) -> 0.0079279199 | F24: 106 | G24: =IF(F24="-", "-", F24/F$10*100) -> 0.014719605 | H24: 23 | I24: =IF(H24="-", "-", H24/H$10*100) -> 0.0037788486 | J24: 46 | K24: =IF(J24="-", "-", J24/J$10*100) -> 0.00686477 | L24: 13 | M24: =IF(L24="-", "-", L24/L$10*100) -> 0.0042390567 | N24: 3 | O24: =IF(N24="-", "-", N24/N$10*100) -> 0.0028938535
B25: Moldovean | C25: Tătar | D25: 12 | E25: =IF(D25="-", "-", D25/D$10*100) -> 0.00049808921 | F25: 7 | G25: =IF(F25="-", "-", F25/F$10*100) -> 0.00097204941 | H25: 2 | I25: =IF(H25="-", "-", H25/H$10*100) -> 0.00032859553 | J25: 2 | K25: =IF(J25="-", "-", J25/J$10*100) -> 0.00029846826 | L25: 1 | M25: =IF(L25="-", "-", L25/L$10*100) -> 0.00032608129 | N25: - | O25: =IF(N25="-", "-", N25/N$10*100) -> -
B26: Moldovean | C26: Gruzin / Georgian | D26: 23 | E26: =IF(D26="-", "-", D26/D$10*100) -> 0.00095467098 | F26: 15 | G26: =IF(F26="-", "-", F26/F$10*100) -> 0.002082963 | H26: 3 | I26: =IF(H26="-", "-", H26/H$10*100) -> 0.0004928933 | J26: 4 | K26: =IF(J26="-", "-", J26/J$10*100) -> 0.00059693652 | L26: 1 | M26: =IF(L26="-", "-", L26/L$10*100) -> 0.00032608129 | N26: - | O26: =IF(N26="-", "-", N26/N$10*100) -> -
B27: Moldovean | C27: Grec | D27: 50 | E27: =IF(D27="-", "-", D27/D$10*100) -> 0.0020753717 | F27: 23 | G27: =IF(F27="-", "-", F27/F$10*100) -> 0.0031938766 | H27: 8 | I27: =IF(H27="-", "-", H27/H$10*100) -> 0.0013143821 | J27: 14 | K27: =IF(J27="-", "-", J27/J$10*100) -> 0.0020892778 | L27: 5 | M27: =IF(L27="-", "-", L27/L$10*100) -> 0.0016304064 | N27: - | O27: =IF(N27="-", "-", N27/N$10*100) -> -
B28: Moldovean | C28: Ceh | D28: 21 | E28: =IF(D28="-", "-", D28/D$10*100) -> 0.00087165611 | F28: 4 | G28: =IF(F28="-", "-", F28/F$10*100) -> 0.00055545681 | H28: 8 | I28: =IF(H28="-", "-", H28/H$10*100) -> 0.0013143821 | J28: 5 | K28: =IF(J28="-", "-", J28/J$10*100) -> 0.00074617065 | L28: 4 | M28: =IF(L28="-", "-", L28/L$10*100) -> 0.0013043251 | N28: - | O28: =IF(N28="-", "-", N28/N$10*100) -> -
